Workbook
Name P_hat: 'Part E'!$C$26

Sheet README
A1: ITI Statistics — Case Study 02: "The Placement Report"
A3: This pack contains THREE datasets. Each one is clean — the mess was Day 1's lesson.
A4: Day 2 is about a different difficulty: the data is fine, and you still have to decide
A5: which distribution describes it and which comparison is legitimate.
A7: Sheets
A8: graduates — 300 graduates. Scores, salaries, interviews, offers, days to first offer.
A9: helpdesk — 180 days of support tickets logged at the training labs.
A10: lab_task — 120 timed task completions at two branches.
A11: data_dictionary — column meanings and units.
A13: The one rule
A14: Every time you use a formula that assumes a distribution — normal, binomial, Poisson —
A15: you must first state WHY that assumption is reasonable for that specific column.
A16: Corrected version: all Part A–D and Part B/C calculation formulas use workbook-local references and legacy-compatible Excel functions; no FILTER/modern dynamic-array formulas or broken [1] external references remain in the core calculations.

Sheet graduates
A1: grad_id | B1: track | C1: assessment_score | D1: starting_salary_k | E1: interviews | F1: offers | G1: days_to_first_offer
A2: G-1001 | B2: Data Science | C2: 73.2 | D2: 16.8 | E2: 7 | F2: 5 | G2: 69
A3: G-1002 | B3: Data Science | C3: 77.5 | D3: 16.4 | E3: 6 | F3: 2 | G3: 43
A4: G-1003 | B4: Data Science | C4: 88.9 | D4: 12.2 | E4: 7 | F4: 4 | G4: 23
A5: G-1004 | B5: Data Science | C5: 74.9 | D5: 13.3 | E5: 6 | F5: 1 | G5: 174
A6: G-1005 | B6: Data Science | C6: 93.4 | D6: 45.2 | E6: 5 | F6: 3 | G6: 59
A7: G-1006 | B7: Data Science | C7: 74.7 | D7: 11.1 | E7: 4 | F7: 1 | G7: 58
A8: G-1007 | B8: Data Science | C8: 79 | D8: 8.6 | E8: 2 | F8: 0 | G8: 66
A9: G-1008 | B9: Data Science | C9: 74.1 | D9: 24 | E9: 2 | F9: 1 | G9: 29
A10: G-1009 | B10: Data Science | C10: 80.8 | D10: 17.6 | E10: 9 | F10: 3 | G10: 36
A11: G-1010 | B11: Data Science | C11: 71.6 | D11: 10.9 | E11: 6 | F11: 1 | G11: 67
A12: G-1011 | B12: Data Science | C12: 73.2 | D12: 7.1 | E12: 6 | F12: 2 | G12: 100
A13: G-1012 | B13: Data Science | C13: 73.9 | D13: 22.1 | E13: 10 | F13: 2 | G13: 85
... A301: G-1300 | B301: UI/UX | C301: 83.7 | D301: 7.4 | E301: 6 | F301: 2 | G301: 24

Sheet helpdesk
A1: date | B1: lab | C1: tickets_logged
A2: 2025-09-01 | B2: Lab C | C2: 3
A3: 2025-09-02 | B3: Lab C | C3: 3
A4: 2025-09-03 | B4: Lab A | C4: 6
A5: 2025-09-04 | B5: Lab C | C5: 5
A6: 2025-09-05 | B6: Lab A | C6: 7
A7: 2025-09-06 | B7: Lab C | C7: 3
A8: 2025-09-07 | B8: Lab C | C8: 2
A9: 2025-09-08 | B9: Lab C | C9: 2
A10: 2025-09-09 | B10: Lab C | C10: 4
A11: 2025-09-10 | B11: Lab B | C11: 2
A12: 2025-09-11 | B12: Lab B | C12: 8
A13: 2025-09-12 | B13: Lab A | C13: 7
... A181: 2026-02-27 | B181: Lab B | C181: 3

Sheet lab_task
A1: student_ref | B1: branch | C1: task_minutes
A2: T-001 | B2: Cairo | C2: 14.9
A3: T-002 | B3: Cairo | C3: 13.8
A4: T-003 | B4: Cairo | C4: 15
A5: T-004 | B5: Cairo | C5: 8
A6: T-005 | B6: Cairo | C6: 15.1
A7: T-006 | B7: Cairo | C7: 19.3
A8: T-007 | B8: Cairo | C8: 15.2
A9: T-008 | B9: Cairo | C9: 12.7
A10: T-009 | B10: Cairo | C10: 18
A11: T-010 | B11: Cairo | C11: 15
A12: T-011 | B12: Cairo | C12: 15.2
A13: T-012 | B13: Cairo | C13: 20
... A121: T-120 | B121: Alexandria | C121: 11.7

Sheet data_dictionary
A1: Sheet | B1: Column | C1: Meaning | D1: Unit / range
A2: graduates | B2: grad_id | C2: Anonymous graduate code | D2: G-1001 …
A3: graduates | B3: track | C3: Training track | D3: 4 tracks
A4: graduates | B4: assessment_score | C4: Final assessment result | D4: 0–100
A5: graduates | B5: starting_salary_k | C5: First-job monthly salary | D5: thousands of L.E.
A6: graduates | B6: interviews | C6: Interviews attended | D6: count, 1–18
A7: graduates | B7: offers | C7: Job offers received | D7: count, 0 to interviews
A8: graduates | B8: days_to_first_offer | C8: Days from graduation to first offer | D8: days
A9: helpdesk | B9: date | C9: Calendar date | D9: 2025-09-01 onward, 180 days
A10: helpdesk | B10: lab | C10: Which training lab logged it | D10: Lab A / B / C
A11: helpdesk | B11: tickets_logged | C11: Support tickets opened that day | D11: count
A12: lab_task | B12: student_ref | C12: Anonymous participant code | D12: T-001 …
... A14: lab_task | B14: task_minutes | C14: Time to complete a standard task | D14: minutes

Sheet Part_A_Dispersion
A1: Part A — Is the Comparison Even Fair? (Dispersion & CV)
A3: A1 — Assessment Score: Mean, Std, CV per track
A4: Track | B4: N | C4: Mean Score | D4: Std Dev (sample) | E4: CV % = (Std/Mean)*100 | F4: Rank by Std (1=highest) | G4: Rank by CV (1=highest)
A5: Data Science | B5: =COUNTIF(graduates!$B$2:$B$301,$A5) -> 95 | C5: =AVERAGEIF(graduates!$B$2:$B$301,$A5,graduates!$C$2:$C$301) -> 77.667368 | D5: =SQRT(SUMPRODUCT((graduates!$B$2:$B$301=$A5)*(graduates!$C$2:$C$301-C5)^2)/(B5-1)) -> 5.8158522 | E5: =$D5/$C5*100 -> 7.488154 | F5: =RANK($D5,$D$5:$D$8) -> 3 | G5: =RANK($E5,$E$5:$E$8) -> 3
A6: Web Development | B6: =COUNTIF(graduates!$B$2:$B$301,$A6) -> 88 | C6: =AVERAGEIF(graduates!$B$2:$B$301,$A6,graduates!$C$2:$C$301) -> 72.118182 | D6: =SQRT(SUMPRODUCT((graduates!$B$2:$B$301=$A6)*(graduates!$C$2:$C$301-C6)^2)/(B6-1)) -> 8.6421521 | E6: =$D6/$C6*100 -> 11.983319 | F6: =RANK($D6,$D$5:$D$8) -> 2 | G6: =RANK($E6,$E$5:$E$8) -> 2
A7: Cyber Security | B7: =COUNTIF(graduates!$B$2:$B$301,$A7) -> 62 | C7: =AVERAGEIF(graduates!$B$2:$B$301,$A7,graduates!$C$2:$C$301) -> 75.15 | D7: =SQRT(SUMPRODUCT((graduates!$B$2:$B$301=$A7)*(graduates!$C$2:$C$301-C7)^2)/(B7-1)) -> 4.1123066 | E7: =$D7/$C7*100 -> 5.4721312 | F7: =RANK($D7,$D$5:$D$8) -> 4 | G7: =RANK($E7,$E$5:$E$8) -> 4
A8: UI/UX | B8: =COUNTIF(graduates!$B$2:$B$301,$A8) -> 55 | C8: =AVERAGEIF(graduates!$B$2:$B$301,$A8,graduates!$C$2:$C$301) -> 71.350909 | D8: =SQRT(SUMPRODUCT((graduates!$B$2:$B$301=$A8)*(graduates!$C$2:$C$301-C8)^2)/(B8-1)) -> 11.276851 | E8: =$D8/$C8*100 -> 15.804775 | F8: =RANK($D8,$D$5:$D$8) -> 1 | G8: =RANK($E8,$E$5:$E$8) -> 1
A9: Ratio: highest CV / lowest CV | E9: =MAX($E$5:$E$8)/MIN($E$5:$E$8) -> 2.8882303
A10: Answers — A1: 1) Ranking by Std and by CV AGREE here (see Rank columns) because score is the same unit (0-100) for all tracks, so CV adds little in this comparison. 2) UI/UX has ~3x the relative variability of Cyber Security (see ratio above). Meaning: Cyber Security students cluster tightly around the mean; UI/UX students range from much weaker to much stronger than their own mean. 3) The mean is NOT a good summary for UI/UX because its spread is by far the largest — the mean hides both very strong and very weak graduates inside the same track.
A12: A1 (continued) — Score vs Salary: why raw Std cannot compare them
A13: Variable | B13: Overall Mean | C13: Overall Std | D13: Overall CV %
A14: Assessment Score (0-100) | B14: =AVERAGE(graduates!$C$2:$C$301) -> 74.361333 | C14: =STDEV(graduates!$C$2:$C$301) -> 8.0951638 | D14: =C14/B14*100 -> 10.886254
A15: Starting Salary (k L.E.) | B15: =AVERAGE(graduates!$D$2:$D$301) -> 15.595 | C15: =STDEV(graduates!$D$2:$D$301) -> 5.9855127 | D15: =C15/B15*100 -> 38.380973
A16: The two Std Dev values are in different units (score points vs. thousand L.E.) so they CANNOT be compared directly. Only CV% (unit-free) answers 'which is more variable': Salary's CV is far higher than Score's CV, so salary is the more variable measure — something raw standard deviation could never tell us.
A18: A2 — Starting Salary: Mean vs Median vs CV per track
A19: Track | B19: N | C19: Mean Salary (k) | D19: Median Salary (k) | E19: Mean > Median? | F19: Std Salary | G19: CV Salary %
A20: Data Science | B20: =COUNTIF(graduates!$B$2:$B$301,$A20) -> 95 | C20: =AVERAGEIF(graduates!$B$2:$B$301,$A20,graduates!$D$2:$D$301) -> 17.953684 | E20: =IF(C20>D20,"YES","no") -> YES | F20: =SQRT(SUMPRODUCT((graduates!$B$2:$B$301=$A20)*(graduates!$D$2:$D$301-C20)^2)/(B20-1)) -> 6.9162591 | G20: =$F20/$C20*100 -> 38.522785
A21: Web Development | B21: =COUNTIF(graduates!$B$2:$B$301,$A21) -> 88 | C21: =AVERAGEIF(graduates!$B$2:$B$301,$A21,graduates!$D$2:$D$301) -> 14.009091 | E21: =IF(C21>D21,"YES","no") -> YES | F21: =SQRT(SUMPRODUCT((graduates!$B$2:$B$301=$A21)*(graduates!$D$2:$D$301-C21)^2)/(B21-1)) -> 4.784569 | G21: =$F21/$C21*100 -> 34.153315
A22: Cyber Security | B22: =COUNTIF(graduates!$B$2:$B$301,$A22) -> 62 | C22: =AVERAGEIF(graduates!$B$2:$B$301,$A22,graduates!$D$2:$D$301) -> 16.491935 | E22: =IF(C22>D22,"YES","no") -> YES | F22: =SQRT(SUMPRODUCT((graduates!$B$2:$B$301=$A22)*(graduates!$D$2:$D$301-C22)^2)/(B22-1)) -> 5.7590783 | G22: =$F22/$C22*100 -> 34.920573
A23: UI/UX | B23: =COUNTIF(graduates!$B$2:$B$301,$A23) -> 55 | C23: =AVERAGEIF(graduates!$B$2:$B$301,$A23,graduates!$D$2:$D$301) -> 13.047273 | E23: =IF(C23>D23,"YES","no") -> YES | F23: =SQRT(SUMPRODUCT((graduates!$B$2:$B$301=$A23)*(graduates!$D$2:$D$301-C23)^2)/(B23-1)) -> 4.3971731 | G23: =$F23/$C23*100 -> 33.701856
A24: ALL 300 (overall) | B24: =COUNT(graduates!$D$2:$D$301) -> 300 | C24: =AVERAGE(graduates!$D$2:$D$301) -> 15.595 | D24: =MEDIAN(graduates!$D$2:$D$301) -> 14.9 | E24: =IF(C24>D24,"YES","no") -> YES | F24: =STDEV(graduates!$D$2:$D$301) -> 5.9855127 | G24: =F24/C24*100 -> 38.380973
A25: Answers — A2: 1-2) Mean > Median in EVERY track (see 'Mean > Median?' column = YES throughout). This is the signature of a right-skewed (positively skewed) distribution — a minority of high earners pulls the mean upward. The report should have quoted the MEDIAN, which is not distorted by that minority. 3) CV of salary is similar across all 4 tracks (roughly 34%-39%, see CV Salary % column) — much closer together than the CV differences we saw for scores. This means: UI/UX salaries are lower in LEVEL, but NOT more unequally distributed inside the track than any other track. 'Lower' and 'more unequal' are two different findings, and the original report conflated them.

Sheet Part_B_Standardization
A1: PART B — STANDARDIZATION & Z-SCORES
A4: B1 — Ranking reversal
A5: Candidate | B5: Track | C5: Raw score | D5: Track mean | E5: Sample SD | F5: Z-score | G5: Relative standing | H5: Why it matters
A6: Candidate A | B6: Cyber Security | C6: =VALUE("82") -> 82 | D6: =AVERAGEIF(graduates!$B$2:$B$301,$B6,graduates!$C$2:$C$301) -> 75.15 | E6: {=SQRT(SUMPRODUCT((graduates!$B$2:$B$301=$B6)*(graduates!$C$2:$C$301-D6)^2)/(COUNTIF(graduates!$B$2:$B$301,$B6)-1))} -> 4.1123066 | F6: =(C6-D6)/E6 -> 1.6657318 | G6: =IF(F6=MAX(F$6:F$7),"Higher relative standing","Lower relative standing") -> Higher relative standing | H6: ="Z = "&TEXT(F6,"0.0000")&" SD from the track mean" -> Z = 1.6657 SD from the track mean
A7: Candidate B | B7: UI/UX | C7: =VALUE("84") -> 84 | D7: =AVERAGEIF(graduates!$B$2:$B$301,$B7,graduates!$C$2:$C$301) -> 71.350909 | E7: =SQRT(SUMPRODUCT((graduates!$B$2:$B$301=$B7)*(graduates!$C$2:$C$301-D7)^2)/(COUNTIF(graduates!$B$2:$B$301,$B7)-1)) -> 11.276851 | F7: =(C7-D7)/E7 -> 1.1216865 | G7: =IF(F7=MAX(F$6:F$7),"Higher relative standing","Lower relative standing") -> Lower relative standing | H7: ="Z = "&TEXT(F7,"0.0000")&" SD from the track mean" -> Z = 1.1217 SD from the track mean
A8: ="Decision: "&IF(F6>F7,"Candidate A is stronger relative to peers.","Candidate B is stronger relative to peers.")&" The raw-score ranking reverses because each score is judged against its own track distribution." -> Decision: Candidate A is stronger relative to peers. The raw-score ranking reverses because each score is judged against its own track distribution.
A11: B2 — Days to first offer
A12: Metric | B12: Mean | C12: Sample SD | D12: Observed | E12: Z-score | F12: Direction | G12: Interpretation | H12: Status
A13: days_to_first_offer | B13: =AVERAGE(graduates!$G$2:$G$301) -> 57.783333 | C13: =STDEV(graduates!$G$2:$G$301) -> 37.594248 | D13: =VALUE("15") -> 15 | E13: =(D13-B13)/C13 -> -1.1380287 | F13: ="Lower is better" -> Lower is better | G13: ="15 days is "&TEXT(ABS(E13),"0.0000")&" SD below the mean." -> 15 days is 1.1380 SD below the mean. | H13: =IF(E13<0,"Good news","Needs context") -> Good news
A16: B3 — Standardisation check
A17: Check | B17: Result | C17: Expected | D17: Status | E17: Interpretation
A18: Mean of 300 Z-scores | B18: =AVERAGE(Z_Scores!$F$5:$F$304) -> -2.6423308e-16 | C18: =0 -> 0 | D18: =IF(ABS(B18-C18)<0.000001,"PASS","CHECK") -> PASS | E18: Centred at zero.
A19: Sample SD of 300 Z-scores | B19: =STDEV(Z_Scores!$F$5:$F$304) -> 0.99497063 | C19: =1 -> 1 | D19: =IF(ABS(B19-C19)<0.01,"PASS","CHECK") -> PASS | E19: Standardised spread.
A20: Population SD (reference) | B20: =STDEVP(Z_Scores!$F$5:$F$304) -> 0.99331096 | C20: =1 -> 1 | D20: "REFERENCE" | E20: Additional consistency check.
A23: B — Final takeaway
A24: The mean is essentially 0 because each track is centered around its own mean. The SD is approximately 1 because each track is scaled by its own standard deviation; the slight difference from exactly 1 results from combining groups with different sample sizes.

Sheet Part_C_Analysis
A1: PART C — NORMALITY, EMPIRICAL RULE & SKEWNESS
A4: C1 — Is a normal approximation reasonable?
A5: Dataset | B5: N | C5: Mean | D5: Median | E5: Mode | F5: Skewness | G5: Statistical Assessment
A6: Data Science assessment | B6: =COUNTIF(graduates!$B$2:$B$301,"Data Science") -> 95 | C6: =AVERAGEIF(graduates!$B$2:$B$301,"Data Science",graduates!$C$2:$C$301) -> 77.667368 | D6: {=MEDIAN(_xlfn._xlws.FILTER(graduates!$C$2:$C$301, graduates!$B$2:$B$301="Data Science"))} -> 77.4 | E6: {=_xlfn.TEXTJOIN(", ", TRUE(), _xlfn.MODE.MULT(IF(graduates!$B$2:$B$301="Data Science", graduates!$C$2:$C$301)))} -> 73.9, 77.3 | F6: =ABS((_xlfn.QUARTILE.INC(graduates!$C$5:$C$99,3)+_xlfn.QUARTILE.INC(graduates!$C$5:$C$99,1)-(2*MEDIAN(graduates!$C$5:$C$99)))/(_xlfn.QUARTILE.INC(graduates!$C$5:$C$99,3)-_xlfn.QUARTILE.INC(graduates!$C$5:$C$99,1))) -> 0.047619048 | G6: ="Low skewness ("&TEXT(F6,"0.0000")&") supports a roughly symmetric shape." -> Low skewness (0.0476) supports a roughly symmetric shape.
A7: Overall starting salary | B7: =COUNT(graduates!$D$2:$D$301) -> 300 | C7: =AVERAGE(graduates!$D$2:$D$301) -> 15.595 | D7: =MEDIAN(graduates!$D$2:$D$301) -> 14.9 | E7: =MODE(graduates!$D$2:$D$301) -> 16.5 | F7: =(_xlfn.QUARTILE.INC(graduates!$D$2:$D$301, 3) + _xlfn.QUARTILE.INC(graduates!$D$2:$D$301, 1) - 2 * MEDIAN(graduates!$D$2:$D$301)) / (_xlfn.QUARTILE.INC(graduates!$D$2:$D$301, 3) - _xlfn.QUARTILE.INC(graduates!$D$2:$D$301, 1)) -> 0.024390244 | G7: ="Right-skewed ("&TEXT(F7,"0.0000")&") — normal salary formulas need caution." -> Right-skewed (0.0244) — normal salary formulas need caution.
A10: C2 — 68–95–99.7 rule for Data Science
A11: Item | B11: Formula result | C11: Meaning | D11: Comparison
A12: Sample SD | B12: {=STDEV(_xlfn._xlws.FILTER(graduates!$C$2:$C$301, graduates!$B$2:$B$301="Data Science"))} -> 5.8158522 | C12: Spread | D12: Formula-derived
A13: About 68% | B13: =TEXT($C$6-$B$12,"0.0000")&" to "&TEXT($C$6+$B$12,"0.0000") -> 71.8515 to 83.4832 | C13: Mean ± 1 SD | D13: ≈68% if normal
A14: About 95% | B14: =TEXT($C$6-2*$B$12,"0.0000")&" to "&TEXT($C$6+2*$B$12,"0.0000") -> 66.0357 to 89.2991 | C14: Mean ± 2 SD | D14: ≈95% if normal
A15: Estimated P(score > mean + 2SD) | B15: =2.5% -> 0.025 | C15: Empirical-rule upper tail | D15: ≈2.5%
A16: Threshold score (mean + 2SD) | B16: =$C$6+2*$B$12 -> 89.299073 | C16: =$C$6&" + 2×"&$B$12 -> 77.6673684210526 + 2×5.81585218331253 | D16: Formula-derived threshold
A17: Observed above threshold | B17: =COUNTIFS(graduates!$B$2:$B$301,"Data Science",graduates!$C$2:$C$301,">"&B16) -> 2 | C17: =B17/$B$6 -> 0.021052632 | D17: =TEXT(B17,"0")&" of "&TEXT($B$6,"0")&" = "&TEXT(C17,"0.00%") -> 2 of 95 = 2.11%
A19: C3 — Salary skewness by track (Bowley)
A20: Track | B20: Q1 | C20: Median | D20: Q3 | E20: Bowley | F20: Shape | H20: Track | I20: Bowley
A21: Cyber Security | B21: {=QUARTILE(IF(graduates!$B$2:$B$301=A21, graduates!$D$2:$D$301), 1)} -> 12.4 | C21: {=MEDIAN(IF(graduates!$B$2:$B$301=A21, graduates!$D$2:$D$301))} -> 15.45 | D21: {=QUARTILE(IF(graduates!$B$2:$B$301=A21, graduates!$D$2:$D$301), 3)} -> 20.525 | E21: =((D21-C21)-(C21-B21))/(D21-B21) -> 0.24923077 | F21: =IF(E21>0.1,"Right-skewed",IF(E21<-0.1,"Left-skewed","Near symmetric")) -> Right-skewed | H21: =A21 -> Cyber Security | I21: =E21 -> 0.24923077
A22: Data Science | B22: {=QUARTILE(IF(graduates!$B$2:$B$301=A22, graduates!$D$2:$D$301), 1)} -> 13.4 | C22: {=MEDIAN(IF(graduates!$B$2:$B$301=A22, graduates!$D$2:$D$301))} -> 16.9 | D22: {=QUARTILE(IF(graduates!$B$2:$B$301=A22, graduates!$D$2:$D$301), 3)} -> 20.9 | E22: =((D22-C22)-(C22-B22))/(D22-B22) -> 0.066666667 | F22: =IF(E22>0.1,"Right-skewed",IF(E22<-0.1,"Left-skewed","Near symmetric")) -> Near symmetric | H22: =A22 -> Data Science | I22: =E22 -> 0.066666667
A23: UI/UX | B23: {=QUARTILE(IF(graduates!$B$2:$B$301=A23, graduates!$D$2:$D$301), 1)} -> 9.85 | C23: {=MEDIAN(IF(graduates!$B$2:$B$301=A23, graduates!$D$2:$D$301))} -> 12.4 | D23: {=QUARTILE(IF(graduates!$B$2:$B$301=A23, graduates!$D$2:$D$301), 3)} -> 15 | E23: =((D23-C23)-(C23-B23))/(D23-B23) -> 0.0097087379 | F23: =IF(E23>0.1,"Right-skewed",IF(E23<-0.1,"Left-skewed","Near symmetric")) -> Near symmetric | H23: =A23 -> UI/UX | I23: =E23 -> 0.0097087379
A24: Web Development | B24: {=QUARTILE(IF(graduates!$B$2:$B$301=A24, graduates!$D$2:$D$301), 1)} -> 10.1 | C24: {=MEDIAN(IF(graduates!$B$2:$B$301=A24, graduates!$D$2:$D$301))} -> 13.45 | D24: {=QUARTILE(IF(graduates!$B$2:$B$301=A24, graduates!$D$2:$D$301), 3)} -> 16.5 | E24: =((D24-C24)-(C24-B24))/(D24-B24) -> -0.046875 | F24: =IF(E24>0.1,"Right-skewed",IF(E24<-0.1,"Left-skewed","Near symmetric")) -> Near symmetric | H24: =A24 -> Web Development | I24: =E24 -> -0.046875
H33: Score interval | I33: Count
H34: =C_Distributions!C6 -> 60–<65 | I34: =C_Distributions!D6 -> 1
H35: =C_Distributions!C7 -> 65–<70 | I35: =C_Distributions!D7 -> 7
H36: =C_Distributions!C8 -> 70–<75 | I36: =C_Distributions!D8 -> 26
H37: =C_Distributions!C9 -> 75–<80 | I37: =C_Distributions!D9 -> 29
H38: =C_Distributions!C10 -> 80–<85 | I38: =C_Distributions!D10 -> 22
H39: =C_Distributions!C11 -> 85–<90 | I39: =C_Distributions!D11 -> 8
H40: =C_Distributions!C12 -> 90–<95 | I40: =C_Distributions!D12 -> 2
A44: C — Final conclusion
A45: ="Conclusion: Data Science assessment has low skewness ("&TEXT(F6,"0.0000")&"), so the empirical-rule exercise is reasonable. The theoretical upper tail above +2 SD is "&TEXT(B15,"0.0%")&"; the observed rate is "&TEXT(C17,"0.00%")&". The minor difference exists because: (1) real sample data is discrete, and (2) sampling variation in n=300 causes small deviations from theoretical limits. Starting salary is right-skewed ("&TEXT(F7,"0.0000")&"), so a normal model should not be assumed for salary without qualification." -> Conclusion: Data Science assessment has low skewness (0.0476), so the empirical-rule exercise is reasonable. The theoretical upper tail above +2 SD is 2.5%; the observed rate is 2.11%. The minor difference exists because: (1) real sample data is discrete, and (2) sampling variation in n=300 causes small deviations from theoretical limits. Starting salary is right-skewed (0.0244), so a normal model should not be assumed for salary without qualification.
A49: For a positively skewed distribution, the theoretical ordering is Mean > Median > Mode. In this sample, mean (15.595) > median (14.9), confirming right-skewness, but the observed mode (16.5) does not follow the textbook ordering; this is possible because the mode is sensitive to the most frequent observed value.
A51: UI/UX is nearly symmetric (Bowley skewness = 0.0097), while Cyber Security is right-skewed (0.2492). UI/UX therefore has a more balanced salary distribution. In Cyber Security, a smaller number of graduates earn substantially higher salaries, pulling the mean upward; the median may be more representative of a typical graduate's salary.

Sheet Part_D_BoxPlots
A1: Part D — Box Plots: Lab Task Time, Cairo vs Alexandria | M1: Cairo times | N1: Alexandria times | O1: Cairo >= lower fence | P1: Cairo <= upper fence | Q1: Alexandria >= lower fence | R1: Alexandria <= upper fence
M2: =IF(lab_task!$B$2=$A$5,lab_task!$C$2,"") -> 14.9 | N2: =IF(lab_task!$B$2=$A$6,lab_task!$C$2,"") | O2: =IF(AND(M2<>"",M2>=$I$5),M2,"") -> 14.9 | P2: =IF(AND(M2<>"",M2<=$J$5),M2,"") -> 14.9 | Q2: =IF(AND(N2<>"",N2>=$I$6),N2,"") | R2: =IF(AND(N2<>"",N2<=$J$6),N2,"")
A3: D1 — Five-Number Summary & Fences | M3: =IF(lab_task!$B$3=$A$5,lab_task!$C$3,"") -> 13.8 | N3: =IF(lab_task!$B$3=$A$6,lab_task!$C$3,"") | O3: =IF(AND(M3<>"",M3>=$I$5),M3,"") -> 13.8 | P3: =IF(AND(M3<>"",M3<=$J$5),M3,"") -> 13.8 | Q3: =IF(AND(N3<>"",N3>=$I$6),N3,"") | R3: =IF(AND(N3<>"",N3<=$J$6),N3,"")
A4: Branch | B4: N | C4: Min | D4: Q1 | E4: Median | F4: Q3 | G4: Max | H4: IQR | I4: Lower Fence | J4: Upper Fence | K4: Whisker Low End | L4: Whisker High End | M4: =IF(lab_task!$B$4=$A$5,lab_task!$C$4,"") -> 15 | N4: =IF(lab_task!$B$4=$A$6,lab_task!$C$4,"") | O4: =IF(AND(M4<>"",M4>=$I$5),M4,"") -> 15 | P4: =IF(AND(M4<>"",M4<=$J$5),M4,"") -> 15 | Q4: =IF(AND(N4<>"",N4>=$I$6),N4,"") | R4: =IF(AND(N4<>"",N4<=$J$6),N4,"")
A5: Cairo | B5: =COUNTIF(lab_task!$B$2:$B$121,$A5) -> 60 | C5: =MIN(M$2:M$121) -> 7.7 | D5: =QUARTILE(M$2:M$121,1) -> 12.075 | E5: =MEDIAN(M$2:M$121) -> 13.85 | F5: =QUARTILE(M$2:M$121,3) -> 15.725 | G5: =MAX(M$2:M$121) -> 20 | H5: =F5-D5 -> 3.65 | I5: =D5-1.5*H5 -> 6.6 | J5: =F5+1.5*H5 -> 21.2 | K5: =MIN(O$2:O$121) -> 7.7 | L5: =MAX(P$2:P$121) -> 20 | M5: =IF(lab_task!$B$5=$A$5,lab_task!$C$5,"") -> 8 | N5: =IF(lab_task!$B$5=$A$6,lab_task!$C$5,"") | O5: =IF(AND(M5<>"",M5>=$I$5),M5,"") -> 8 | P5: =IF(AND(M5<>"",M5<=$J$5),M5,"") -> 8 | Q5: =IF(AND(N5<>"",N5>=$I$6),N5,"") | R5: =IF(AND(N5<>"",N5<=$J$6),N5,"")
A6: Alexandria | B6: =COUNTIF(lab_task!$B$2:$B$121,$A6) -> 60 | C6: =MIN(N$2:N$121) -> 7.1 | D6: =QUARTILE(N$2:N$121,1) -> 11.775 | E6: =MEDIAN(N$2:N$121) -> 15.3 | F6: =QUARTILE(N$2:N$121,3) -> 19.85 | G6: =MAX(N$2:N$121) -> 44.7 | H6: =F6-D6 -> 8.075 | I6: =D6-1.5*H6 -> -0.3375 | J6: =F6+1.5*H6 -> 31.9625 | K6: =MIN(Q$2:Q$121) -> 7.1 | L6: =MAX(R$2:R$121) -> 29.1 | M6: =IF(lab_task!$B$6=$A$5,lab_task!$C$6,"") -> 15.1 | N6: =IF(lab_task!$B$6=$A$6,lab_task!$C$6,"") | O6: =IF(AND(M6<>"",M6>=$I$5),M6,"") -> 15.1 | P6: =IF(AND(M6<>"",M6<=$J$5),M6,"") -> 15.1 | Q6: =IF(AND(N6<>"",N6>=$I$6),N6,"") | R6: =IF(AND(N6<>"",N6<=$J$6),N6,"")
M7: =IF(lab_task!$B$7=$A$5,lab_task!$C$7,"") -> 19.3 | N7: =IF(lab_task!$B$7=$A$6,lab_task!$C$7,"") | O7: =IF(AND(M7<>"",M7>=$I$5),M7,"") -> 19.3 | P7: =IF(AND(M7<>"",M7<=$J$5),M7,"") -> 19.3 | Q7: =IF(AND(N7<>"",N7>=$I$6),N7,"") | R7: =IF(AND(N7<>"",N7<=$J$6),N7,"")
A8: Outliers (values outside the fences) | M8: =IF(lab_task!$B$8=$A$5,lab_task!$C$8,"") -> 15.2 | N8: =IF(lab_task!$B$8=$A$6,lab_task!$C$8,"") | O8: =IF(AND(M8<>"",M8>=$I$5),M8,"") -> 15.2 | P8: =IF(AND(M8<>"",M8<=$J$5),M8,"") -> 15.2 | Q8: =IF(AND(N8<>"",N8>=$I$6),N8,"") | R8: =IF(AND(N8<>"",N8<=$J$6),N8,"")
A9: Branch | B9: Outlier Count | C9: Outlier Values | M9: =IF(lab_task!$B$9=$A$5,lab_task!$C$9,"") -> 12.7 | N9: =IF(lab_task!$B$9=$A$6,lab_task!$C$9,"") | O9: =IF(AND(M9<>"",M9>=$I$5),M9,"") -> 12.7 | P9: =IF(AND(M9<>"",M9<=$J$5),M9,"") -> 12.7 | Q9: =IF(AND(N9<>"",N9>=$I$6),N9,"") | R9: =IF(AND(N9<>"",N9<=$J$6),N9,"")
A10: Cairo | B10: =SUMPRODUCT((lab_task!$B$2:$B$121=$A10)*((lab_task!$C$2:$C$121<$I$5)+(lab_task!$C$2:$C$121>$J$5))) -> 0 | C10: =IF(B10=0,"None",IF(B10=1,"1 outlier — see source data",TEXT(B10,"0")&" outliers — see source data")) -> None | M10: =IF(lab_task!$B$10=$A$5,lab_task!$C$10,"") -> 18 | N10: =IF(lab_task!$B$10=$A$6,lab_task!$C$10,"") | O10: =IF(AND(M10<>"",M10>=$I$5),M10,"") -> 18 | P10: =IF(AND(M10<>"",M10<=$J$5),M10,"") -> 18 | Q10: =IF(AND(N10<>"",N10>=$I$6),N10,"") | R10: =IF(AND(N10<>"",N10<=$J$6),N10,"")
A11: Alexandria | B11: =SUMPRODUCT((lab_task!$B$2:$B$121=$A11)*((lab_task!$C$2:$C$121<$I$6)+(lab_task!$C$2:$C$121>$J$6))) -> 3 | C11: =IF(B11=0,"None",IF(B11=1,"1 outlier — see source data",TEXT(B11,"0")&" outliers — see source data")) -> 3 outliers — see source data | M11: =IF(lab_task!$B$11=$A$5,lab_task!$C$11,"") -> 15 | N11: =IF(lab_task!$B$11=$A$6,lab_task!$C$11,"") | O11: =IF(AND(M11<>"",M11>=$I$5),M11,"") -> 15 | P11: =IF(AND(M11<>"",M11<=$J$5),M11,"") -> 15 | Q11: =IF(AND(N11<>"",N11>=$I$6),N11,"") | R11: =IF(AND(N11<>"",N11<=$J$6),N11,"")
A12: Answers — D1: 1) Five-number summary for each branch is in the table above (Min / Q1 / Median / Q3 / Max). 2) Cairo has ZERO outliers (Outlier Count = 0). Alexandria has 3 outliers, all above its upper fence (listed above). 3) The whisker does NOT extend to the fence itself — it stops at the most extreme observation still inside the fence. See 'Whisker Low End' / 'Whisker High End' columns: for Alexandria the high whisker stops well short of its Max (44.7), because the 3 outliers were excluded from the whisker. 4) See the attached PNG chart (Part D box plot) for the shared-axis drawing with outliers marked in red. | M12: =IF(lab_task!$B$12=$A$5,lab_task!$C$12,"") -> 15.2 | N12: =IF(lab_task!$B$12=$A$6,lab_task!$C$12,"") | O12: =IF(AND(M12<>"",M12>=$I$5),M12,"") -> 15.2 | P12: =IF(AND(M12<>"",M12<=$J$5),M12,"") -> 15.2 | Q12: =IF(AND(N12<>"",N12>=$I$6),N12,"") | R12: =IF(AND(N12<>"",N12<=$J$6),N12,"")
M13: =IF(lab_task!$B$13=$A$5,lab_task!$C$13,"") -> 20 | N13: =IF(lab_task!$B$13=$A$6,lab_task!$C$13,"") | O13: =IF(AND(M13<>"",M13>=$I$5),M13,"") -> 20 | P13: =IF(AND(M13<>"",M13<=$J$5),M13,"") -> 20 | Q13: =IF(AND(N13<>"",N13>=$I$6),N13,"") | R13: =IF(AND(N13<>"",N13<=$J$6),N13,"")
A14: D2 — Reading the Plot | M14: =IF(lab_task!$B$14=$A$5,lab_task!$C$14,"") -> 15.5 | N14: =IF(lab_task!$B$14=$A$6,lab_task!$C$14,"") | O14: =IF(AND(M14<>"",M14>=$I$5),M14,"") -> 15.5 | P14: =IF(AND(M14<>"",M14<=$J$5),M14,"") -> 15.5 | Q14: =IF(AND(N14<>"",N14>=$I$6),N14,"") | R14: =IF(AND(N14<>"",N14<=$J$6),N14,"")
A15: Branch | B15: Median | C15: Q3-Median | D15: Median-Q1 | E15: Skew Direction | F15: IQR | M15: =IF(lab_task!$B$15=$A$5,lab_task!$C$15,"") -> 12.1 | N15: =IF(lab_task!$B$15=$A$6,lab_task!$C$15,"") | O15: =IF(AND(M15<>"",M15>=$I$5),M15,"") -> 12.1 | P15: =IF(AND(M15<>"",M15<=$J$5),M15,"") -> 12.1 | Q15: =IF(AND(N15<>"",N15>=$I$6),N15,"") | R15: =IF(AND(N15<>"",N15<=$J$6),N15,"")
A16: Cairo | B16: =E5 -> 13.85 | C16: =F5-E5 -> 1.875 | D16: =E5-D5 -> 1.775 | E16: =IF(C16>D16,"Right-skewed",IF(C16<D16,"Left-skewed","Symmetric")) -> Right-skewed | F16: =H5 -> 3.65 | M16: =IF(lab_task!$B$16=$A$5,lab_task!$C$16,"") -> 11.5 | N16: =IF(lab_task!$B$16=$A$6,lab_task!$C$16,"") | O16: =IF(AND(M16<>"",M16>=$I$5),M16,"") -> 11.5 | P16: =IF(AND(M16<>"",M16<=$J$5),M16,"") -> 11.5 | Q16: =IF(AND(N16<>"",N16>=$I$6),N16,"") | R16: =IF(AND(N16<>"",N16<=$J$6),N16,"")
A17: Alexandria | B17: =E6 -> 15.3 | C17: =F6-E6 -> 4.55 | D17: =E6-D6 -> 3.525 | E17: =IF(C17>D17,"Right-skewed",IF(C17<D17,"Left-skewed","Symmetric")) -> Right-skewed | F17: =H6 -> 8.075 | M17: =IF(lab_task!$B$17=$A$5,lab_task!$C$17,"") -> 17.4 | N17: =IF(lab_task!$B$17=$A$6,lab_task!$C$17,"") | O17: =IF(AND(M17<>"",M17>=$I$5),M17,"") -> 17.4 | P17: =IF(AND(M17<>"",M17<=$J$5),M17,"") -> 17.4 | Q17: =IF(AND(N17<>"",N17>=$I$6),N17,"") | R17: =IF(AND(N17<>"",N17<=$J$6),N17,"")
A18: Median difference (Alexandria - Cairo) | E18: =E6-E5 -> 1.45 | M18: =IF(lab_task!$B$18=$A$5,lab_task!$C$18,"") -> 9.2 | N18: =IF(lab_task!$B$18=$A$6,lab_task!$C$18,"") | O18: =IF(AND(M18<>"",M18>=$I$5),M18,"") -> 9.2 | P18: =IF(AND(M18<>"",M18<=$J$5),M18,"") -> 9.2 | Q18: =IF(AND(N18<>"",N18>=$I$6),N18,"") | R18: =IF(AND(N18<>"",N18<=$J$6),N18,"")
A19: Answers — D2: 1) Alexandria has the higher median (see difference above, ~1.45 minutes higher than Cairo). 2) Skew Direction column: Cairo is close to symmetric (Q3-Median ≈ Median-Q1). Alexandria is right-skewed (Q3-Median > Median-Q1) — a minority of slow completions stretch the upper tail. 3) IQR: Cairo's IQR is much smaller than Alexandria's — Cairo is far more CONSISTENT. 'Slower on average' (median) and 'less consistent' (IQR) are two separate findings; the lab manager's claim ('Alexandria is slower') only captures the median part. 4) The 3 Alexandria outliers look like genuine slow completions, not data-entry errors (per the error-vs-outlier distinction from Case Study 01) — they should stay in the analysis unless there is a real-world reason (e.g. a documented interruption) to justify removing a specific one. Decision-note: for a deadline-sensitive task, Cairo is the safer choice — lower median AND far less variability, so wait times are more predictable. | M19: =IF(lab_task!$B$19=$A$5,lab_task!$C$19,"") -> 12.5 | N19: =IF(lab_task!$B$19=$A$6,lab_task!$C$19,"") | O19: =IF(AND(M19<>"",M19>=$I$5),M19,"") -> 12.5 | P19: =IF(AND(M19<>"",M19<=$J$5),M19,"") -> 12.5 | Q19: =IF(AND(N19<>"",N19>=$I$6),N19,"") | R19: =IF(AND(N19<>"",N19<=$J$6),N19,"")
M20: =IF(lab_task!$B$20=$A$5,lab_task!$C$20,"") -> 12 | N20: =IF(lab_task!$B$20=$A$6,lab_task!$C$20,"") | O20: =IF(AND(M20<>"",M20>=$I$5),M20,"") -> 12 | P20: =IF(AND(M20<>"",M20<=$J$5),M20,"") -> 12 | Q20: =IF(AND(N20<>"",N20>=$I$6),N20,"") | R20: =IF(AND(N20<>"",N20<=$J$6),N20,"")
M21: =IF(lab_task!$B$21=$A$5,lab_task!$C$21,"") -> 17 | N21: =IF(lab_task!$B$21=$A$6,lab_task!$C$21,"") | O21: =IF(AND(M21<>"",M21>=$I$5),M21,"") -> 17 | P21: =IF(AND(M21<>"",M21<=$J$5),M21,"") -> 17 | Q21: =IF(AND(N21<>"",N21>=$I$6),N21,"") | R21: =IF(AND(N21<>"",N21<=$J$6),N21,"")
M22: =IF(lab_task!$B$22=$A$5,lab_task!$C$22,"") -> 13.4 | N22: =IF(lab_task!$B$22=$A$6,lab_task!$C$22,"") | O22: =IF(AND(M22<>"",M22>=$I$5),M22,"") -> 13.4 | P22: =IF(AND(M22<>"",M22<=$J$5),M22,"") -> 13.4 | Q22: =IF(AND(N22<>"",N22>=$I$6),N22,"") | R22: =IF(AND(N22<>"",N22<=$J$6),N22,"")
M23: =IF(lab_task!$B$23=$A$5,lab_task!$C$23,"") -> 14.6 | N23: =IF(lab_task!$B$23=$A$6,lab_task!$C$23,"") | O23: =IF(AND(M23<>"",M23>=$I$5),M23,"") -> 14.6 | P23: =IF(AND(M23<>"",M23<=$J$5),M23,"") -> 14.6 | Q23: =IF(AND(N23<>"",N23>=$I$6),N23,"") | R23: =IF(AND(N23<>"",N23<=$J$6),N23,"")
M24: =IF(lab_task!$B$24=$A$5,lab_task!$C$24,"") -> 8.4 | N24: =IF(lab_task!$B$24=$A$6,lab_task!$C$24,"") | O24: =IF(AND(M24<>"",M24>=$I$5),M24,"") -> 8.4 | P24: =IF(AND(M24<>"",M24<=$J$5),M24,"") -> 8.4 | Q24: =IF(AND(N24<>"",N24>=$I$6),N24,"") | R24: =IF(AND(N24<>"",N24<=$J$6),N24,"")
M25: =IF(lab_task!$B$25=$A$5,lab_task!$C$25,"") -> 12.5 | N25: =IF(lab_task!$B$25=$A$6,lab_task!$C$25,"") | O25: =IF(AND(M25<>"",M25>=$I$5),M25,"") -> 12.5 | P25: =IF(AND(M25<>"",M25<=$J$5),M25,"") -> 12.5 | Q25: =IF(AND(N25<>"",N25>=$I$6),N25,"") | R25: =IF(AND(N25<>"",N25<=$J$6),N25,"")
M26: =IF(lab_task!$B$26=$A$5,lab_task!$C$26,"") -> 13.9 | N26: =IF(lab_task!$B$26=$A$6,lab_task!$C$26,"") | O26: =IF(AND(M26<>"",M26>=$I$5),M26,"") -> 13.9 | P26: =IF(AND(M26<>"",M26<=$J$5),M26,"") -> 13.9 | Q26: =IF(AND(N26<>"",N26>=$I$6),N26,"") | R26: =IF(AND(N26<>"",N26<=$J$6),N26,"")
M27: =IF(lab_task!$B$27=$A$5,lab_task!$C$27,"") -> 13.9 | N27: =IF(lab_task!$B$27=$A$6,lab_task!$C$27,"") | O27: =IF(AND(M27<>"",M27>=$I$5),M27,"") -> 13.9 | P27: =IF(AND(M27<>"",M27<=$J$5),M27,"") -> 13.9 | Q27: =IF(AND(N27<>"",N27>=$I$6),N27,"") | R27: =IF(AND(N27<>"",N27<=$J$6),N27,"")
M28: =IF(lab_task!$B$28=$A$5,lab_task!$C$28,"") -> 14 | N28: =IF(lab_task!$B$28=$A$6,lab_task!$C$28,"") | O28: =IF(AND(M28<>"",M28>=$I$5),M28,"") -> 14 | P28: =IF(AND(M28<>"",M28<=$J$5),M28,"") -> 14 | Q28: =IF(AND(N28<>"",N28>=$I$6),N28,"") | R28: =IF(AND(N28<>"",N28<=$J$6),N28,"")
M29: =IF(lab_task!$B$29=$A$5,lab_task!$C$29,"") -> 15.8 | N29: =IF(lab_task!$B$29=$A$6,lab_task!$C$29,"") | O29: =IF(AND(M29<>"",M29>=$I$5),M29,"") -> 15.8 | P29: =IF(AND(M29<>"",M29<=$J$5),M29,"") -> 15.8 | Q29: =IF(AND(N29<>"",N29>=$I$6),N29,"") | R29: =IF(AND(N29<>"",N29<=$J$6),N29,"")
M30: =IF(lab_task!$B$30=$A$5,lab_task!$C$30,"") -> 14.8 | N30: =IF(lab_task!$B$30=$A$6,lab_task!$C$30,"") | O30: =IF(AND(M30<>"",M30>=$I$5),M30,"") -> 14.8 | P30: =IF(AND(M30<>"",M30<=$J$5),M30,"") -> 14.8 | Q30: =IF(AND(N30<>"",N30>=$I$6),N30,"") | R30: =IF(AND(N30<>"",N30<=$J$6),N30,"")
M31: =IF(lab_task!$B$31=$A$5,lab_task!$C$31,"") -> 18 | N31: =IF(lab_task!$B$31=$A$6,lab_task!$C$31,"") | O31: =IF(AND(M31<>"",M31>=$I$5),M31,"") -> 18 | P31: =IF(AND(M31<>"",M31<=$J$5),M31,"") -> 18 | Q31: =IF(AND(N31<>"",N31>=$I$6),N31,"") | R31: =IF(AND(N31<>"",N31<=$J$6),N31,"")
M32: =IF(lab_task!$B$32=$A$5,lab_task!$C$32,"") -> 12.4 | N32: =IF(lab_task!$B$32=$A$6,lab_task!$C$32,"") | O32: =IF(AND(M32<>"",M32>=$I$5),M32,"") -> 12.4 | P32: =IF(AND(M32<>"",M32<=$J$5),M32,"") -> 12.4 | Q32: =IF(AND(N32<>"",N32>=$I$6),N32,"") | R32: =IF(AND(N32<>"",N32<=$J$6),N32,"")
M33: =IF(lab_task!$B$33=$A$5,lab_task!$C$33,"") -> 13.6 | N33: =IF(lab_task!$B$33=$A$6,lab_task!$C$33,"") | O33: =IF(AND(M33<>"",M33>=$I$5),M33,"") -> 13.6 | P33: =IF(AND(M33<>"",M33<=$J$5),M33,"") -> 13.6 | Q33: =IF(AND(N33<>"",N33>=$I$6),N33,"") | R33: =IF(AND(N33<>"",N33<=$J$6),N33,"")
M34: =IF(lab_task!$B$34=$A$5,lab_task!$C$34,"") -> 12.7 | N34: =IF(lab_task!$B$34=$A$6,lab_task!$C$34,"") | O34: =IF(AND(M34<>"",M34>=$I$5),M34,"") -> 12.7 | P34: =IF(AND(M34<>"",M34<=$J$5),M34,"") -> 12.7 | Q34: =IF(AND(N34<>"",N34>=$I$6),N34,"") | R34: =IF(AND(N34<>"",N34<=$J$6),N34,"")
M35: =IF(lab_task!$B$35=$A$5,lab_task!$C$35,"") -> 18.7 | N35: =IF(lab_task!$B$35=$A$6,lab_task!$C$35,"") | O35: =IF(AND(M35<>"",M35>=$I$5),M35,"") -> 18.7 | P35: =IF(AND(M35<>"",M35<=$J$5),M35,"") -> 18.7 | Q35: =IF(AND(N35<>"",N35>=$I$6),N35,"") | R35: =IF(AND(N35<>"",N35<=$J$6),N35,"")
M36: =IF(lab_task!$B$36=$A$5,lab_task!$C$36,"") -> 17.8 | N36: =IF(lab_task!$B$36=$A$6,lab_task!$C$36,"") | O36: =IF(AND(M36<>"",M36>=$I$5),M36,"") -> 17.8 | P36: =IF(AND(M36<>"",M36<=$J$5),M36,"") -> 17.8 | Q36: =IF(AND(N36<>"",N36>=$I$6),N36,"") | R36: =IF(AND(N36<>"",N36<=$J$6),N36,"")
M37: =IF(lab_task!$B$37=$A$5,lab_task!$C$37,"") -> 10 | N37: =IF(lab_task!$B$37=$A$6,lab_task!$C$37,"") | O37: =IF(AND(M37<>"",M37>=$I$5),M37,"") -> 10 | P37: =IF(AND(M37<>"",M37<=$J$5),M37,"") -> 10 | Q37: =IF(AND(N37<>"",N37>=$I$6),N37,"") | R37: =IF(AND(N37<>"",N37<=$J$6),N37,"")
M38: =IF(lab_task!$B$38=$A$5,lab_task!$C$38,"") -> 10.2 | N38: =IF(lab_task!$B$38=$A$6,lab_task!$C$38,"") | O38: =IF(AND(M38<>"",M38>=$I$5),M38,"") -> 10.2 | P38: =IF(AND(M38<>"",M38<=$J$5),M38,"") -> 10.2 | Q38: =IF(AND(N38<>"",N38>=$I$6),N38,"") | R38: =IF(AND(N38<>"",N38<=$J$6),N38,"")
M39: =IF(lab_task!$B$39=$A$5,lab_task!$C$39,"") -> 16.7 | N39: =IF(lab_task!$B$39=$A$6,lab_task!$C$39,"") | O39: =IF(AND(M39<>"",M39>=$I$5),M39,"") -> 16.7 | P39: =IF(AND(M39<>"",M39<=$J$5),M39,"") -> 16.7 | Q39: =IF(AND(N39<>"",N39>=$I$6),N39,"") | R39: =IF(AND(N39<>"",N39<=$J$6),N39,"")
M40: =IF(lab_task!$B$40=$A$5,lab_task!$C$40,"") -> 17.1 | N40: =IF(lab_task!$B$40=$A$6,lab_task!$C$40,"") | O40: =IF(AND(M40<>"",M40>=$I$5),M40,"") -> 17.1 | P40: =IF(AND(M40<>"",M40<=$J$5),M40,"") -> 17.1 | Q40: =IF(AND(N40<>"",N40>=$I$6),N40,"") | R40: =IF(AND(N40<>"",N40<=$J$6),N40,"")
...

Sheet B_C_Completed
A1: PART B + PART C — Completed Statistical Analysis
A2: All standard deviations below use the sample SD (STDEV.S), consistent with Part A. Values are calculated directly from the supplied 300-graduate dataset.
A4: B1 — Standardized values and the ranking reversal
A5: Candidate | B5: Track | C5: Raw score | D5: Track mean | E5: Track SD | F5: Z-score | G5: Relative conclusion | H5: Formula / logic
A6: Candidate A | B6: Cyber Security | C6: 82 | D6: 75.15 | E6: 4.1123066 | F6: 1.6657318 | G6: Stronger relative to peers | H6: Z = (82 − 75.1500) / 4.1123 = 1.6657
A7: Candidate B | B7: UI/UX | C7: 84 | D7: 71.350909 | E7: 11.276851 | F7: 1.1216865 | G7: Weaker relative to peers | H7: Z = (84 − 71.3509) / 11.2769 = 1.1217
A9: Answer to B1.2 | B9: Candidate A is stronger relative to their own peers, despite the lower raw score, because 82 is 1.6657 SD above the Cyber Security mean while 84 is only 1.1217 SD above the UI/UX mean.
A11: Recruiter recommendation | B11: Recommend Candidate A if the assessment is the main comparable criterion. The decision should also consider role fit, relevant projects/portfolio, technical skills, interview performance, communication, experience, and track-specific job requirements.
A14: B2 — Direction matters
A15: Measure | B15: Mean | C15: Sample SD | D15: Observed value | E15: Z-score | F15: Direction | G15: Interpretation | H15: General rule
A16: days_to_first_offer | B16: 57.783333 | C16: 37.594248 | D16: 15 | E16: -1.1380287 | F16: Lower is better | G16: GOOD NEWS: 15 days is 1.1380 SD below the overall mean, so the graduate received an offer faster than average. | H16: A Z-score has no universal good/bad sign; judge the sign using whether higher or lower values are desirable.
B18: Contrast with assessment_score: | C18: For assessment score, higher is better, so a large negative Z would be unfavorable. For days_to_first_offer, lower is better, so a large negative Z is favorable.
A21: B3 — Standardizing assessment scores within track
A22: Check | B22: Result | C22: Expected / target | D22: Formula / explanation | E22: Status
A23: Mean of 300 Z-values | B23: -2.3684758e-17 | C23: ≈ 0 | D23: Zᵢ = (scoreᵢ − track mean) / track sample SD | E23: PASS
A24: Sample SD of 300 Z-values | B24: 0.99497063 | C24: ≈ 1 | D24: STDEV.S(all 300 within-track Z-values) | E24: PASS
A25: Population SD of 300 Z-values | B25: 0.99331096 | C25: ≈ 1 | D25: STDEV.P(all 300 within-track Z-values) | E25: Reference
A27: Why this happens | B27: Each track is centered at its own mean and scaled by its own SD, so the combined standardized values have mean essentially 0; using sample SDs within each track gives a combined sample SD of 0.994971, extremely close to 1.
A30: C1 — Check the normality assumption first
A31: Dataset | B31: N | C31: Mean | D31: Median | E31: Mode(s) | F31: Skewness (moment) | G31: Normality decision | H31: Numerical evidence
A32: Data Science assessment_score | B32: 95 | C32: 77.667368 | D32: 77.4 | E32: 73.9, 77.3 | F32: 0.076709826 | G32: Reasonable for the empirical-rule exercise | H32: Mean ≈ median; skewness = 0.0767; histogram is broadly bell-shaped/symmetric.
A33: All starting_salary_k | B33: 300 | C33: 15.595 | D33: 14.9 | E33: 16.5 | F33: 1.3853822 | G33: Do NOT assume normal | H33: Skewness = 1.3854 (strong positive/right skew); mean > median and the distribution has a long upper tail.
A35: C1.2 | B35: For Data Science, mean = 77.6674, median = 77.4000, and modes = 73.9 and 77.3. They are close enough, together with skewness 0.0767, to support the normal approximation used in C2.
A37: C1.3 | B37: No for starting salary: the numerical skewness is 1.3854, and mean = 15.595 while median = 14.900, indicating substantial right-skew. A normal model would be a poor assumption.
A40: C2 — Apply the 68–95–99.7 empirical rule
A41: Question | B41: Calculation | C41: Answer | D41: Interpretation
A42: 68% interval | B42: 77.6674 ± 5.8159 | C42: 71.8515 to 83.4832 | D42: Roughly 68% of Data Science scores.
A43: 95% interval | B43: 77.6674 ± 2(5.8159) | C43: 66.0357 to 89.2991 | D43: Roughly 95% of Data Science scores.
A44: P(score > 89.3) | B44: 89.3 ≈ mean + 2SD = 89.2991 | C44: ≈ 2.5% theoretical | D44: Upper tail beyond +2 SD under the normal empirical rule.
A45: Observed above threshold | B45: Count(score > 89.2991) / 95 | C45: 2/95 = 2.11% | D45: Observed proportion in the supplied Data Science sample.
A47: Why theory and data do not match exactly | B47: (1) The empirical rule is an approximation based on an assumed normal population, while the real sample is finite and not perfectly normal. (2) Sampling variability means the observed count will naturally differ from the theoretical 2.5%, even when the model is reasonable.
A51: C3 — Skewness measured rather than labelled
A52: Group | B52: Q1 | C52: Median (Q2) | D52: Q3 | E52: Bowley skewness | F52: Interpretation
A53: Overall salary | B53: 11.4 | C53: 14.9 | D53: 18.575 | E53: 0.024390244 | F53: Very close to symmetric by Bowley’s quartile measure, but the moment skewness (1.3854) reveals a long upper tail.
A54: Cyber Security | B54: 12.4 | C54: 15.45 | D54: 20.525 | E54: 0.24923077 | F54: Positive/right-skewed
A55: Data Science | B55: 13.4 | C55: 16.9 | D55: 20.9 | E55: 0.066666667 | F55: Mild skew
A56: UI/UX | B56: 9.85 | C56: 12.4 | D56: 15 | E56: 0.0097087379 | F56: Very close to symmetric
A57: Web Development | B57: 10.1 | C57: 13.45 | D57: 16.5 | E57: -0.046875 | F57: Very close to symmetric
A59: C3.1–C3.3 conclusion | B59: Sign: positive means the upper/right side is longer; negative means the lower/left side is longer. UI/UX is closest to symmetric (Bowley = 0.0097), while Cyber Security is the most clearly right-skewed by this quartile measure (0.2492). Overall salary has Bowley = 0.0244, but its moment skewness is 1.3854, showing that extreme upper salaries affect the tail.

Sheet Z_Scores
A1: 300 Graduate Assessment Z-Scores — Within Track
A4: grad_id | B4: track | C4: assessment_score | D4: Track mean | E4: Track SD | F4: Z-score | G4: Z-score formula | I4: Validation
A5: G-1001 | B5: Data Science | C5: 73.2 | D5: =AVERAGEIF(graduates!$B$2:$B$301,$B5,graduates!$C$2:$C$301) -> 77.667368 | E5: =SQRT(SUMPRODUCT((graduates!$B$2:$B$301=$B5)*(graduates!$C$2:$C$301-D5)^2)/(COUNTIF(graduates!$B$2:$B$301,$B5)-1)) -> 5.8158522 | F5: =(C5-D5)/E5 -> -0.76813651 | G5: =(C5-D5)/E5 -> -0.76813651 | I5: Mean of Z | J5: =AVERAGE(G5:G304) -> -2.6423308e-16
A6: G-1002 | B6: Data Science | C6: 77.5 | D6: =AVERAGEIF(graduates!$B$2:$B$301,$B6,graduates!$C$2:$C$301) -> 77.667368 | E6: =SQRT(SUMPRODUCT((graduates!$B$2:$B$301=$B6)*(graduates!$C$2:$C$301-D6)^2)/(COUNTIF(graduates!$B$2:$B$301,$B6)-1)) -> 5.8158522 | F6: =(C6-D6)/E6 -> -0.02877797 | G6: =(C6-D6)/E6 -> -0.02877797 | I6: Sample SD of Z | J6: =STDEV(G5:G304) -> 0.99497063
A7: G-1003 | B7: Data Science | C7: 88.9 | D7: =AVERAGEIF(graduates!$B$2:$B$301,$B7,graduates!$C$2:$C$301) -> 77.667368 | E7: =SQRT(SUMPRODUCT((graduates!$B$2:$B$301=$B7)*(graduates!$C$2:$C$301-D7)^2)/(COUNTIF(graduates!$B$2:$B$301,$B7)-1)) -> 5.8158522 | F7: =(C7-D7)/E7 -> 1.9313819 | G7: =(C7-D7)/E7 -> 1.9313819 | I7: Population SD of Z | J7: =STDEVP(G5:G304) -> 0.99331096
A8: G-1004 | B8: Data Science | C8: 74.9 | D8: =AVERAGEIF(graduates!$B$2:$B$301,$B8,graduates!$C$2:$C$301) -> 77.667368 | E8: =SQRT(SUMPRODUCT((graduates!$B$2:$B$301=$B8)*(graduates!$C$2:$C$301-D8)^2)/(COUNTIF(graduates!$B$2:$B$301,$B8)-1)) -> 5.8158522 | F8: =(C8-D8)/E8 -> -0.47583197 | G8: =(C8-D8)/E8 -> -0.47583197
A9: G-1005 | B9: Data Science | C9: 93.4 | D9: =AVERAGEIF(graduates!$B$2:$B$301,$B9,graduates!$C$2:$C$301) -> 77.667368 | E9: =SQRT(SUMPRODUCT((graduates!$B$2:$B$301=$B9)*(graduates!$C$2:$C$301-D9)^2)/(COUNTIF(graduates!$B$2:$B$301,$B9)-1)) -> 5.8158522 | F9: =(C9-D9)/E9 -> 2.7051292 | G9: =(C9-D9)/E9 -> 2.7051292
A10: G-1006 | B10: Data Science | C10: 74.7 | D10: =AVERAGEIF(graduates!$B$2:$B$301,$B10,graduates!$C$2:$C$301) -> 77.667368 | E10: =SQRT(SUMPRODUCT((graduates!$B$2:$B$301=$B10)*(graduates!$C$2:$C$301-D10)^2)/(COUNTIF(graduates!$B$2:$B$301,$B10)-1)) -> 5.8158522 | F10: =(C10-D10)/E10 -> -0.51022074 | G10: =(C10-D10)/E10 -> -0.51022074
A11: G-1007 | B11: Data Science | C11: 79 | D11: =AVERAGEIF(graduates!$B$2:$B$301,$B11,graduates!$C$2:$C$301) -> 77.667368 | E11: =SQRT(SUMPRODUCT((graduates!$B$2:$B$301=$B11)*(graduates!$C$2:$C$301-D11)^2)/(COUNTIF(graduates!$B$2:$B$301,$B11)-1)) -> 5.8158522 | F11: =(C11-D11)/E11 -> 0.2291378 | G11: =(C11-D11)/E11 -> 0.2291378
A12: G-1008 | B12: Data Science | C12: 74.1 | D12: =AVERAGEIF(graduates!$B$2:$B$301,$B12,graduates!$C$2:$C$301) -> 77.667368 | E12: =SQRT(SUMPRODUCT((graduates!$B$2:$B$301=$B12)*(graduates!$C$2:$C$301-D12)^2)/(COUNTIF(graduates!$B$2:$B$301,$B12)-1)) -> 5.8158522 | F12: =(C12-D12)/E12 -> -0.61338705 | G12: =(C12-D12)/E12 -> -0.61338705
A13: G-1009 | B13: Data Science | C13: 80.8 | D13: =AVERAGEIF(graduates!$B$2:$B$301,$B13,graduates!$C$2:$C$301) -> 77.667368 | E13: =SQRT(SUMPRODUCT((graduates!$B$2:$B$301=$B13)*(graduates!$C$2:$C$301-D13)^2)/(COUNTIF(graduates!$B$2:$B$301,$B13)-1)) -> 5.8158522 | F13: =(C13-D13)/E13 -> 0.53863673 | G13: =(C13-D13)/E13 -> 0.53863673
A14: G-1010 | B14: Data Science | C14: 71.6 | D14: =AVERAGEIF(graduates!$B$2:$B$301,$B14,graduates!$C$2:$C$301) -> 77.667368 | E14: =SQRT(SUMPRODUCT((graduates!$B$2:$B$301=$B14)*(graduates!$C$2:$C$301-D14)^2)/(COUNTIF(graduates!$B$2:$B$301,$B14)-1)) -> 5.8158522 | F14: =(C14-D14)/E14 -> -1.0432467 | G14: =(C14-D14)/E14 -> -1.0432467
A15: G-1011 | B15: Data Science | C15: 73.2 | D15: =AVERAGEIF(graduates!$B$2:$B$301,$B15,graduates!$C$2:$C$301) -> 77.667368 | E15: =SQRT(SUMPRODUCT((graduates!$B$2:$B$301=$B15)*(graduates!$C$2:$C$301-D15)^2)/(COUNTIF(graduates!$B$2:$B$301,$B15)-1)) -> 5.8158522 | F15: =(C15-D15)/E15 -> -0.76813651 | G15: =(C15-D15)/E15 -> -0.76813651
A16: G-1012 | B16: Data Science | C16: 73.9 | D16: =AVERAGEIF(graduates!$B$2:$B$301,$B16,graduates!$C$2:$C$301) -> 77.667368 | E16: =SQRT(SUMPRODUCT((graduates!$B$2:$B$301=$B16)*(graduates!$C$2:$C$301-D16)^2)/(COUNTIF(graduates!$B$2:$B$301,$B16)-1)) -> 5.8158522 | F16: =(C16-D16)/E16 -> -0.64777582 | G16: =(C16-D16)/E16 -> -0.64777582
A17: G-1013 | B17: Data Science | C17: 72.1 | D17: =AVERAGEIF(graduates!$B$2:$B$301,$B17,graduates!$C$2:$C$301) -> 77.667368 | E17: =SQRT(SUMPRODUCT((graduates!$B$2:$B$301=$B17)*(graduates!$C$2:$C$301-D17)^2)/(COUNTIF(graduates!$B$2:$B$301,$B17)-1)) -> 5.8158522 | F17: =(C17-D17)/E17 -> -0.95727475 | G17: =(C17-D17)/E17 -> -0.95727475
A18: G-1014 | B18: Data Science | C18: 77.8 | D18: =AVERAGEIF(graduates!$B$2:$B$301,$B18,graduates!$C$2:$C$301) -> 77.667368 | E18: =SQRT(SUMPRODUCT((graduates!$B$2:$B$301=$B18)*(graduates!$C$2:$C$301-D18)^2)/(COUNTIF(graduates!$B$2:$B$301,$B18)-1)) -> 5.8158522 | F18: =(C18-D18)/E18 -> 0.022805184 | G18: =(C18-D18)/E18 -> 0.022805184
A19: G-1015 | B19: Data Science | C19: 82.5 | D19: =AVERAGEIF(graduates!$B$2:$B$301,$B19,graduates!$C$2:$C$301) -> 77.667368 | E19: =SQRT(SUMPRODUCT((graduates!$B$2:$B$301=$B19)*(graduates!$C$2:$C$301-D19)^2)/(COUNTIF(graduates!$B$2:$B$301,$B19)-1)) -> 5.8158522 | F19: =(C19-D19)/E19 -> 0.83094127 | G19: =(C19-D19)/E19 -> 0.83094127
... A303: G-1299 | B303: UI/UX | C303: 66.1 | D303: =AVERAGEIF(graduates!$B$2:$B$301,$B303,graduates!$C$2:$C$301) -> 71.350909 | E303: =SQRT(SUMPRODUCT((graduates!$B$2:$B$301=$B303)*(graduates!$C$2:$C$301-D303)^2)/(COUNTIF(graduates!$B$2:$B$301,$B303)-1)) -> 11.276851 | F303: =(C303-D303)/E303 -> -0.46563613 | G303: =(C303-D303)/E303 -> -0.46563613
A304: G-1300 | B304: UI/UX | C304: 83.7 | D304: =AVERAGEIF(graduates!$B$2:$B$301,$B304,graduates!$C$2:$C$301) -> 71.350909 | E304: {=SQRT(SUMPRODUCT((graduates!$B$2:$B$301=$B304)*(graduates!$C$2:$C$301-D304)^2)/(COUNTIF(graduates!$B$2:$B$301,$B304)-1))} -> 11.276851 | F304: =(C304-D304)/E304 -> 1.0950833 | G304: =(C304-D304)/E304 -> 1.0950833

Sheet C_Distributions
A1: C1–C3 Distribution Diagnostics & Charts
A4: Data Science assessment_score — histogram counts
A5: Bin lower | B5: Bin upper | C5: Interval | D5: Count
A6: =FLOOR(_xlfn.MINIFS(graduates!$C$2:$C$301,graduates!$B$2:$B$301,"Data Science"),5) -> 60 | B6: =A6+5 -> 65 | C6: =TEXT(A6,"0")&"–<"&TEXT(B6,"0") -> 60–<65 | D6: =COUNTIFS(graduates!$B$2:$B$301,"Data Science",graduates!$C$2:$C$301,">="&A6,graduates!$C$2:$C$301,"<"&B6) -> 1
A7: =B6 -> 65 | B7: =A7+5 -> 70 | C7: =TEXT(A7,"0")&"–<"&TEXT(B7,"0") -> 65–<70 | D7: =COUNTIFS(graduates!$B$2:$B$301,"Data Science",graduates!$C$2:$C$301,">="&A7,graduates!$C$2:$C$301,"<"&B7) -> 7
A8: =B7 -> 70 | B8: =A8+5 -> 75 | C8: =TEXT(A8,"0")&"–<"&TEXT(B8,"0") -> 70–<75 | D8: =COUNTIFS(graduates!$B$2:$B$301,"Data Science",graduates!$C$2:$C$301,">="&A8,graduates!$C$2:$C$301,"<"&B8) -> 26
A9: =B8 -> 75 | B9: =A9+5 -> 80 | C9: =TEXT(A9,"0")&"–<"&TEXT(B9,"0") -> 75–<80 | D9: =COUNTIFS(graduates!$B$2:$B$301,"Data Science",graduates!$C$2:$C$301,">="&A9,graduates!$C$2:$C$301,"<"&B9) -> 29
A10: =B9 -> 80 | B10: =A10+5 -> 85 | C10: =TEXT(A10,"0")&"–<"&TEXT(B10,"0") -> 80–<85 | D10: =COUNTIFS(graduates!$B$2:$B$301,"Data Science",graduates!$C$2:$C$301,">="&A10,graduates!$C$2:$C$301,"<"&B10) -> 22
A11: =B10 -> 85 | B11: =A11+5 -> 90 | C11: =TEXT(A11,"0")&"–<"&TEXT(B11,"0") -> 85–<90 | D11: =COUNTIFS(graduates!$B$2:$B$301,"Data Science",graduates!$C$2:$C$301,">="&A11,graduates!$C$2:$C$301,"<"&B11) -> 8
A12: =B11 -> 90 | B12: =A12+5 -> 95 | C12: =TEXT(A12,"0")&"–<"&TEXT(B12,"0") -> 90–<95 | D12: =COUNTIFS(graduates!$B$2:$B$301,"Data Science",graduates!$C$2:$C$301,">="&A12,graduates!$C$2:$C$301,"<"&B12) -> 2
A20: Starting salary — histogram counts
A21: Bin lower | B21: Bin upper | C21: Interval | D21: Count
A22: 5 | B22: 10 | C22: 5–<10 | D22: =COUNTIFS(graduates!$D$2:$D$301,">="&A22,graduates!$D$2:$D$301,"<"&B22) -> 49
A23: 10 | B23: 15 | C23: 10–<15 | D23: =COUNTIFS(graduates!$D$2:$D$301,">="&A23,graduates!$D$2:$D$301,"<"&B23) -> 102
A24: 15 | B24: 20 | C24: 15–<20 | D24: =COUNTIFS(graduates!$D$2:$D$301,">="&A24,graduates!$D$2:$D$301,"<"&B24) -> 86
A25: 20 | B25: 25 | C25: 20–<25 | D25: =COUNTIFS(graduates!$D$2:$D$301,">="&A25,graduates!$D$2:$D$301,"<"&B25) -> 49
A26: 25 | B26: 30 | C26: 25–<30 | D26: =COUNTIFS(graduates!$D$2:$D$301,">="&A26,graduates!$D$2:$D$301,"<"&B26) -> 5
A27: 30 | B27: 35 | C27: 30–<35 | D27: =COUNTIFS(graduates!$D$2:$D$301,">="&A27,graduates!$D$2:$D$301,"<"&B27) -> 4
A28: 35 | B28: 40 | C28: 35–<40 | D28: =COUNTIFS(graduates!$D$2:$D$301,">="&A28,graduates!$D$2:$D$301,"<"&B28) -> 3
A29: 40 | B29: 45 | C29: 40–<45 | D29: =COUNTIFS(graduates!$D$2:$D$301,">="&A29,graduates!$D$2:$D$301,"<"&B29) -> 1
A30: 45 | B30: 50 | C30: 45–<50 | D30: =COUNTIFS(graduates!$D$2:$D$301,">="&A30,graduates!$D$2:$D$301,"<"&B30) -> 1
A35: Numerical diagnostics
A36: Metric | B36: Data Science assessment | C36: All starting salary | D36: Meaning
A37: Mean | B37: =AVERAGEIF(graduates!B$2:B$301, "Data Science", graduates!C$2:C$301) -> 77.667368 | C37: =AVERAGE(graduates!D$2:D$301) -> 15.595 | D37: Center
A38: Median | B38: {=MEDIAN(IF(graduates!$B$2:$B$301="Data Science", graduates!$C$2:$C$301))} -> 77.4 | C38: =MEDIAN(graduates!D$2:D$301) -> 14.9 | D38: Center resistant to extremes
A39: Mode(s) | B39: {=_xlfn.TEXTJOIN(", ", TRUE(), _xlfn.MODE.MULT(IF(graduates!$B$2:$B$301="Data Science", graduates!$C$2:$C$301)))} -> 73.9, 77.3 | C39: =_xlfn.MODE.SNGL(graduates!D$2:D$301) -> 16.5 | D39: Most frequent value(s)
A40: Moment skewness | B40: {=SKEW(IF(graduates!$B$2:$B$301="Data Science", graduates!$C$2:$C$301))} -> 0.076709826 | C40: =SKEW(graduates!D$2:D$301) -> 1.3853822 | D40: 0 ≈ symmetric; positive = right-skew
A41: Bowley skewness | B41: {=((_xlfn.QUARTILE.INC(IF(graduates!$B$2:$B$301="Data Science", graduates!$C$2:$C$301),3)-MEDIAN(IF(graduates!$B$2:$B$301="Data Science", graduates!$C$2:$C$301)))-(MEDIAN(IF(graduates!$B$2:$B$301="Data Science", graduates!$C$2:$C$301))-_xlfn.QUARTILE.INC(IF(graduates!$B$2:$B$301="Data Science", graduates!$C$2:$C$301),1)))/(_xlfn.QUARTILE.INC(IF(graduates!$B$2:$B$301="Data Science", graduates!$C$2:$C$301),3)-_xlfn.QUARTILE.INC(IF(graduates!$B$2:$B$301="Data Science", graduates!$C$2:$C$301),1))} -> 0.025316456 | C41: =(((_xlfn.QUARTILE.INC(graduates!D$2:D$301,3)-MEDIAN(graduates!D$2:D$301))-(MEDIAN(graduates!D$2:D$301)-_xlfn.QUARTILE.INC(graduates!D$2:D$301,1)))/(_xlfn.QUARTILE.INC(graduates!D$2:D$301,3)-_xlfn.QUARTILE.INC(graduates!D$2:D$301,1))) -> 0.024390244 | D41: Quartile-based skewness
A44: Track salary skewness — Bowley coefficient
A45: Track | B45: Q1 | C45: Median | D45: Q3 | E45: Bowley skewness | F45: Interpretation
A46: Cyber Security | B46: {=QUARTILE(IF(graduates!$B$2:$B$301=A46, graduates!$D$2:$D$301), 1)} -> 12.4 | C46: =Part_C_Analysis!C21 -> 15.45 | D46: {=QUARTILE(IF(graduates!$B$2:$B$301=A46, graduates!$D$2:$D$301), 3)} -> 20.525 | E46: =((D46-C46)-(C46-B46))/(D46-B46) -> 0.24923077 | F46: Right-skewed
A47: Data Science | B47: {=QUARTILE(IF(graduates!$B$2:$B$301=A47, graduates!$D$2:$D$301), 1)} -> 13.4 | C47: =Part_C_Analysis!C22 -> 16.9 | D47: {=QUARTILE(IF(graduates!$B$2:$B$301=A47, graduates!$D$2:$D$301), 3)} -> 20.9 | E47: =((D47-C47)-(C47-B47))/(D47-B47) -> 0.066666667 | F47: Mild skew
A48: UI/UX | B48: {=QUARTILE(IF(graduates!$B$2:$B$301=A48, graduates!$D$2:$D$301), 1)} -> 9.85 | C48: =Part_C_Analysis!C23 -> 12.4 | D48: {=QUARTILE(IF(graduates!$B$2:$B$301=A48, graduates!$D$2:$D$301), 3)} -> 15 | E48: =((D48-C48)-(C48-B48))/(D48-B48) -> 0.0097087379 | F48: Near symmetric
A49: Web Development | B49: {=QUARTILE(IF(graduates!$B$2:$B$301=A49, graduates!$D$2:$D$301), 1)} -> 10.1 | C49: =Part_C_Analysis!C24 -> 13.45 | D49: {=QUARTILE(IF(graduates!$B$2:$B$301=A49, graduates!$D$2:$D$301), 3)} -> 16.5 | E49: =((D49-C49)-(C49-B49))/(D49-B49) -> -0.046875 | F49: Near symmetric
A51: Track | B51: Mean salary | C51: Median salary
A52: Cyber Security | B52: =AVERAGEIF(graduates!$B$2:$B$301,A52,graduates!$D$2:$D$301) -> 16.491935 | C52: {=MEDIAN(IF(graduates!$B$2:$B$301=A52, graduates!$D$2:$D$301))} -> 15.45
A53: Data Science | B53: =AVERAGEIF(graduates!$B$2:$B$301,A53,graduates!$D$2:$D$301) -> 17.953684 | C53: {=MEDIAN(IF(graduates!$B$2:$B$301=A53, graduates!$D$2:$D$301))} -> 16.9
A54: UI/UX | B54: =AVERAGEIF(graduates!$B$2:$B$301,A54,graduates!$D$2:$D$301) -> 13.047273 | C54: {=MEDIAN(IF(graduates!$B$2:$B$301=A54, graduates!$D$2:$D$301))} -> 12.4
A55: Web Development | B55: =AVERAGEIF(graduates!$B$2:$B$301,A55,graduates!$D$2:$D$301) -> 14.009091 | C55: {=MEDIAN(IF(graduates!$B$2:$B$301=A55, graduates!$D$2:$D$301))} -> 13.45

Sheet Part E
B2: E1. Does the binomial even apply?
B4: Condition | C4: Does it hold here? Justify.
B5: A fixed number n of identical trials | C5: Not really across the whole sample. Each graduate does have a fixed n (their own interview count), but n is different for every graduate, so there's no single n for all 300 of them.
B6: Each trial has exactly two outcomes | C6: Yes, this one holds fine. Each interview either ends in an offer or no offer, nothing in between.
B7: The probability of success p is constant across trials | C7: No, this is the one that breaks. Graduates aren't equally skilled, so their real chance of getting an offer isn't the same person to person. Using one pooled p for everyone hides that difference.
B8: The trials are independent | C8: Mostly holds. Companies interview graduates separately, but there could be a small effect where getting rejected a few times in a row affects how someone performs in the next interview (or getting an early offer makes them try less in the rest). Weaker issue than #3 though.
B10: The condition that's most clearly violated is #3 (constant p). Graduates differ in skill and preparation, so each one really has a different chance of landing an offer — it's not the same probability for everyone. When we pool all offers and interviews together to get one average p, we're basically hiding that difference. This makes the binomial model underestimate how many graduates end up with zero offers, because the weaker graduates (whose real p is much lower than the average) get averaged out and disappear into the overall number.
B24: E2. Estimate p and use it
B26: P | C26: =SUM(graduates!F:F) / SUM(graduates!E:E) -> 0.29161604
B28: 2 Offers From 6 Interviews | C28: =_xlfn.BINOM.DIST(2,6,P_hat,FALSE()) -> 0.32120992
B29: No Offers | C29: =_xlfn.BINOM.DIST(0,6,P_hat,FALSE()) -> 0.12636079
B30: At Least One Offer | C30: =1-_xlfn.BINOM.DIST(0,6,P_hat,FALSE()) -> 0.87363921
B31: Mean | C31: =6*P_hat -> 1.7496962
B32: Variance | C32: =6*P_hat*(1-P_hat) -> 1.2394567
B36: E3. Shape, and a reality check
L37: Since p = 0.292 is below 0.5, the binomial distribution for n = 6 is right-skewed (positively skewed). Most of the probability is concentrated at the lower values of x (around 1-2 offers), with a smaller tail extending toward the higher values (5, 6 offers) that have very low probability.
B38: X | C38: P
B39: 0 | C39: =_xlfn.BINOM.DIST(B39,6,P_hat,FALSE()) -> 0.12636079
B40: 1 | C40: =_xlfn.BINOM.DIST(B40,6,P_hat,FALSE()) -> 0.31210897
B41: 2 | C41: =_xlfn.BINOM.DIST(B41,6,P_hat,FALSE()) -> 0.32120992
B42: 3 | C42: =_xlfn.BINOM.DIST(B42,6,P_hat,FALSE()) -> 0.17630733
B43: 4 | C43: =_xlfn.BINOM.DIST(B43,6,P_hat,FALSE()) -> 0.054434511
B44: 5 | C44: =_xlfn.BINOM.DIST(B44,6,P_hat,FALSE()) -> 0.0089634872
B45: 6 | C45: =_xlfn.BINOM.DIST(B45,6,P_hat,FALSE()) -> 0.00061499055
B49: NO. Zero Offer | C49: Percentage
B50: =COUNTIF(graduates!F:F,0) -> 66 | C50: =(66/300) -> 0.22
B54: Prob_Zero_Offers | C54: Average Prob Zero Offers
B55: =_xlfn.BINOM.DIST(0, graduates!E2, P_hat, FALSE()) -> 0.089511954 | C55: =AVERAGE(Table2[Prob_Zero_Offers]) -> 0.19364019 | D55: Observed proportion of graduates with zero offers: 66/300 = 0.22 (22%) Model-predicted proportion (using each graduate's actual number of interviews with p hat = 0.292): 0.194 (19.4%) The binomial model under-predicts — the actual zero-offer rate (22%) is noticeably higher than what the model predicts (19.4%).
B56: =_xlfn.BINOM.DIST(0, graduates!E3, P_hat, FALSE()) -> 0.12636079
B57: =_xlfn.BINOM.DIST(0, graduates!E4, P_hat, FALSE()) -> 0.089511954
B58: =_xlfn.BINOM.DIST(0, graduates!E5, P_hat, FALSE()) -> 0.12636079
B59: =_xlfn.BINOM.DIST(0, graduates!E6, P_hat, FALSE()) -> 0.17837895
B60: =_xlfn.BINOM.DIST(0, graduates!E7, P_hat, FALSE()) -> 0.2518111
B61: =_xlfn.BINOM.DIST(0, graduates!E8, P_hat, FALSE()) -> 0.50180784
B62: =_xlfn.BINOM.DIST(0, graduates!E9, P_hat, FALSE()) -> 0.50180784
B63: =_xlfn.BINOM.DIST(0, graduates!E10, P_hat, FALSE()) -> 0.0449178
B64: =_xlfn.BINOM.DIST(0, graduates!E11, P_hat, FALSE()) -> 0.12636079 | D64: Some graduates are simply stronger candidates than others — better CVs, more interview experience, or a track with better market demand. These stronger candidates have a real chance of success well above the pooled average, while weaker candidates have a real chance well below it. Because the model uses one constant p for everyone, it can't capture this — it assumes every graduate is equally likely to succeed in each interview. In reality, the weaker candidates are the ones getting shut out entirely, which pushes the actual zero-offer rate higher than a constant-p model would ever predict.
B65: =_xlfn.BINOM.DIST(0, graduates!E12, P_hat, FALSE()) -> 0.12636079
B66: =_xlfn.BINOM.DIST(0, graduates!E13, P_hat, FALSE()) -> 0.031819049
B67: =_xlfn.BINOM.DIST(0, graduates!E14, P_hat, FALSE()) -> 0.2518111
...

Sheet Part F
B2: F1. Test the Poisson signature
B4: Metric | C4: Value
B5: Mean of tickets_logged (180 days) | C5: =AVERAGE(helpdesk!C2:C181) -> 3.7055556
B6: Sample variance of tickets_logged | C6: =VAR(helpdesk!C2:C181) -> 3.6055556
B7: Variance minus mean | C7: =C6-C5 -> -0.1
B8: Variance / mean ratio | C8: =C6/C5 -> 0.97301349
B10: ="Mean = "&TEXT(C5,"0.0000")&", variance = "&TEXT(C6,"0.0000")&". They are close (ratio = "&TEXT(C8,"0.00")&"), which is the Poisson signature (mean = variance). This dataset looks consistent with a Poisson process — there is no sign of the extra spread (over-dispersion) or the extra tightness (under-dispersion) that would make you doubt the model." -> Mean = 3.7056, variance = 3.6056. They are close (ratio = 0.97), which is the Poisson signature (mean = variance). This dataset looks consistent with a Poisson process — there is no sign of the extra spread (over-dispersion) or the extra tightness (under-dispersion) that would make you doubt the model.
B14: Condition | C14: Does it hold here? Justify.
B15: The variable is discrete | C15: Yes. tickets_logged is always a whole number of tickets (0, 1, 2, ...). You cannot log half a ticket, so the count is discrete by nature.
B16: Occurrences are random | C16: Reasonably yes. A ticket arrives when a student or staff member happens to hit a problem; there is no schedule forcing tickets to appear at fixed times, so day-to-day counts behave like random arrivals rather than a deterministic pattern.
